<mujoco model="spiral_chain">
  <compiler/>
  <option timestep="0.005" gravity="0 0 -9.81" impratio="10" iterations="50"/>
  <default>
    <joint damping="0.2" stiffness="0.01" limited="true" range="-25.662747418161974 25.662747418161974" solimplimit="0.9 0.95 0.001" solreflimit="0.02 0.5" armature="0.01"/>
    <geom contype="1" conaffinity="0"/>
  </default>
  <worldbody>
    <body name="base" pos="0 0 0">
      <geom type="plane" size="2 2 0.1" rgba="0 0 1 0.6" contype="2" conaffinity="1"/>
      <!-- Der eigentliche Ketten-Root wird hier als Kind erzeugt -->
      <body name="seg_17" pos="0 0 0">
        <joint name="j_17" type="hinge" axis="0 1 0" pos="0 0 0" stiffness="0.05" damping="0.05" limited="true" range="-30.562747418161972 30.562747418161972" solimplimit="0.9 0.95 0.001" solreflimit="0.01 0.5"/>

        <!-- sichtbare, kollisionslose box-->
        <geom name="g_17" type="box"
              size="0.0271576 0.0271576 0.0147807"
              pos="0 0 0.0147807"
              rgba="0.2 0.7 0.2 0.3" contype="1" conaffinity="0" density="1100"/>

        <!-- Tendon-Sites: unten (in) / oben (out) auf äußerster Kante ±x -->
        <site name="site_in_17_0"  pos="0.0260474 0 0.00990682"  size="0.001" rgba="1 1 0 1"/>
        <site name="site_out_17_0" pos="0.0245672 0 0.0253007" size="0.001" rgba="1 1 0 1"/>
        <site name="site_in_17_1"  pos="-0.0260474 0 0.00990682"  size="0.001" rgba="1 1 0 1"/>
        <site name="site_out_17_1" pos="-0.0245672 0 0.0253007" size="0.001" rgba="1 1 0 1"/>

        <!-- Attachment-Punkt für das nächste Segment am Segmentende: -->
        <body name="seg_17_end" pos="0 0 0.0295615">
      <body name="seg_16" pos="0 0 0">
        <joint name="j_16" type="hinge" axis="0 1 0" pos="0 0 0" stiffness="0.05" damping="0.05" limited="true" range="-30.562747418161972 30.562747418161972" solimplimit="0.9 0.95 0.001" solreflimit="0.01 0.5"/>

        <!-- sichtbare, kollisionslose box-->
        <geom name="g_16" type="box"
              size="0.0245844 0.0245844 0.0133803"
              pos="0 0 0.0133803"
              rgba="0.6 0.75 0.95 0.3" contype="1" conaffinity="0" density="1100"/>

        <!-- Tendon-Sites: unten (in) / oben (out) auf äußerster Kante ±x -->
        <site name="site_in_16_0"  pos="0.0233053 0 0.00886387"  size="0.001" rgba="1 1 0 1"/>
        <site name="site_out_16_0" pos="0.0219505 0 0.0229536" size="0.001" rgba="1 1 0 1"/>
        <site name="site_in_16_1"  pos="-0.0233053 0 0.00886387"  size="0.001" rgba="1 1 0 1"/>
        <site name="site_out_16_1" pos="-0.0219505 0 0.0229536" size="0.001" rgba="1 1 0 1"/>

        <!-- Attachment-Punkt für das nächste Segment am Segmentende: -->
        <body name="seg_16_end" pos="0 0 0.0267606">
      <body name="seg_15" pos="0 0 0">
        <joint name="j_15" type="hinge" axis="0 1 0" pos="0 0 0" stiffness="0.05" damping="0.05" limited="true" range="-30.562747418161972 30.562747418161972" solimplimit="0.9 0.95 0.001" solreflimit="0.01 0.5"/>

        <!-- sichtbare, kollisionslose box-->
        <geom name="g_15" type="box"
              size="0.0222551 0.0222551 0.0121125"
              pos="0 0 0.0121125"
              rgba="0.2 0.7 0.2 0.3" contype="1" conaffinity="0" density="1100"/>

        <!-- Tendon-Sites: unten (in) / oben (out) auf äußerster Kante ±x -->
        <site name="site_in_15_0"  pos="0.0208229 0 0.00791974"  size="0.001" rgba="1 1 0 1"/>
        <site name="site_out_15_0" pos="0.0195816 0 0.020829" size="0.001" rgba="1 1 0 1"/>
        <site name="site_in_15_1"  pos="-0.0208229 0 0.00791974"  size="0.001" rgba="1 1 0 1"/>
        <site name="site_out_15_1" pos="-0.0195816 0 0.020829" size="0.001" rgba="1 1 0 1"/>

        <!-- Attachment-Punkt für das nächste Segment am Segmentende: -->
        <body name="seg_15_end" pos="0 0 0.024225">
      <body name="seg_14" pos="0 0 0">
        <joint name="j_14" type="hinge" axis="0 1 0" pos="0 0 0" stiffness="0.05" damping="0.05" limited="true" range="-30.562747418161972 30.562747418161972" solimplimit="0.9 0.95 0.001" solreflimit="0.01 0.5"/>

        <!-- sichtbare, kollisionslose box-->
        <geom name="g_14" type="box"
              size="0.0201465 0.0201465 0.0109649"
              pos="0 0 0.0109649"
              rgba="0.6 0.75 0.95 0.3" contype="1" conaffinity="0" density="1100"/>

        <!-- Tendon-Sites: unten (in) / oben (out) auf äußerster Kante ±x -->
        <site name="site_in_14_0"  pos="0.0185758 0 0.00706506"  size="0.001" rgba="1 1 0 1"/>
        <site name="site_out_14_0" pos="0.0174372 0 0.0189056" size="0.001" rgba="1 1 0 1"/>
        <site name="site_in_14_1"  pos="-0.0185758 0 0.00706506"  size="0.001" rgba="1 1 0 1"/>
        <site name="site_out_14_1" pos="-0.0174372 0 0.0189056" size="0.001" rgba="1 1 0 1"/>

        <!-- Attachment-Punkt für das nächste Segment am Segmentende: -->
        <body name="seg_14_end" pos="0 0 0.0219298">
      <body name="seg_13" pos="0 0 0">
        <joint name="j_13" type="hinge" axis="0 1 0" pos="0 0 0" stiffness="0.05" damping="0.05" limited="true" range="-30.562747418161972 30.562747418161972" solimplimit="0.9 0.95 0.001" solreflimit="0.01 0.5"/>

        <!-- sichtbare, kollisionslose box-->
        <geom name="g_13" type="box"
              size="0.0182376 0.0182376 0.00992598"
              pos="0 0 0.00992598"
              rgba="0.2 0.7 0.2 0.3" contype="1" conaffinity="0" density="1100"/>

        <!-- Tendon-Sites: unten (in) / oben (out) auf äußerster Kante ±x -->
        <site name="site_in_13_0"  pos="0.0165415 0 0.00629136"  size="0.001" rgba="1 1 0 1"/>
        <site name="site_out_13_0" pos="0.015496 0 0.0171644" size="0.001" rgba="1 1 0 1"/>
        <site name="site_in_13_1"  pos="-0.0165415 0 0.00629136"  size="0.001" rgba="1 1 0 1"/>
        <site name="site_out_13_1" pos="-0.015496 0 0.0171644" size="0.001" rgba="1 1 0 1"/>

        <!-- Attachment-Punkt für das nächste Segment am Segmentende: -->
        <body name="seg_13_end" pos="0 0 0.019852">
      <body name="seg_12" pos="0 0 0">
        <joint name="j_12" type="hinge" axis="0 1 0" pos="0 0 0" stiffness="0.05" damping="0.05" limited="true" range="-30.562747418161972 30.562747418161972" solimplimit="0.9 0.95 0.001" solreflimit="0.01 0.5"/>

        <!-- sichtbare, kollisionslose box-->
        <geom name="g_12" type="box"
              size="0.0165096 0.0165096 0.00898551"
              pos="0 0 0.00898551"
              rgba="0.6 0.75 0.95 0.3" contype="1" conaffinity="0" density="1100"/>

        <!-- Tendon-Sites: unten (in) / oben (out) auf äußerster Kante ±x -->
        <site name="site_in_12_0"  pos="0.0147 0 0.00559097"  size="0.001" rgba="1 1 0 1"/>
        <site name="site_out_12_0" pos="0.0137387 0 0.0155883" size="0.001" rgba="1 1 0 1"/>
        <site name="site_in_12_1"  pos="-0.0147 0 0.00559097"  size="0.001" rgba="1 1 0 1"/>
        <site name="site_out_12_1" pos="-0.0137387 0 0.0155883" size="0.001" rgba="1 1 0 1"/>

        <!-- Attachment-Punkt für das nächste Segment am Segmentende: -->
        <body name="seg_12_end" pos="0 0 0.017971">
      <body name="seg_11" pos="0 0 0">
        <joint name="j_11" type="hinge" axis="0 1 0" pos="0 0 0" stiffness="0.05" damping="0.05" limited="true" range="-30.562747418161972 30.562747418161972" solimplimit="0.9 0.95 0.001" solreflimit="0.01 0.5"/>

        <!-- sichtbare, kollisionslose box-->
        <geom name="g_11" type="box"
              size="0.0149454 0.0149454 0.00813415"
              pos="0 0 0.00813415"
              rgba="0.2 0.7 0.2 0.3" contype="1" conaffinity="0" density="1100"/>

        <!-- Tendon-Sites: unten (in) / oben (out) auf äußerster Kante ±x -->
        <site name="site_in_11_0"  pos="0.013033 0 0.00495694"  size="0.001" rgba="1 1 0 1"/>
        <site name="site_out_11_0" pos="0.012148 0 0.0141615" size="0.001" rgba="1 1 0 1"/>
        <site name="site_in_11_1"  pos="-0.013033 0 0.00495694"  size="0.001" rgba="1 1 0 1"/>
        <site name="site_out_11_1" pos="-0.012148 0 0.0141615" size="0.001" rgba="1 1 0 1"/>

        <!-- Attachment-Punkt für das nächste Segment am Segmentende: -->
        <body name="seg_11_end" pos="0 0 0.0162683">
      <body name="seg_10" pos="0 0 0">
        <joint name="j_10" type="hinge" axis="0 1 0" pos="0 0 0" stiffness="0.05" damping="0.05" limited="true" range="-30.562747418161972 30.562747418161972" solimplimit="0.9 0.95 0.001" solreflimit="0.01 0.5"/>

        <!-- sichtbare, kollisionslose box-->
        <geom name="g_10" type="box"
              size="0.0135293 0.0135293 0.00736345"
              pos="0 0 0.00736345"
              rgba="0.6 0.75 0.95 0.3" contype="1" conaffinity="0" density="1100"/>

        <!-- Tendon-Sites: unten (in) / oben (out) auf äußerster Kante ±x -->
        <site name="site_in_10_0"  pos="0.0115239 0 0.00438299"  size="0.001" rgba="1 1 0 1"/>
        <site name="site_out_10_0" pos="0.0107079 0 0.0128698" size="0.001" rgba="1 1 0 1"/>
        <site name="site_in_10_1"  pos="-0.0115239 0 0.00438299"  size="0.001" rgba="1 1 0 1"/>
        <site name="site_out_10_1" pos="-0.0107079 0 0.0128698" size="0.001" rgba="1 1 0 1"/>

        <!-- Attachment-Punkt für das nächste Segment am Segmentende: -->
        <body name="seg_10_end" pos="0 0 0.0147269">
      <body name="seg_9" pos="0 0 0">
        <joint name="j_9" type="hinge" axis="0 1 0" pos="0 0 0" stiffness="0.05" damping="0.05" limited="true" range="-30.562747418161972 30.562747418161972" solimplimit="0.9 0.95 0.001" solreflimit="0.01 0.5"/>

        <!-- sichtbare, kollisionslose box-->
        <geom name="g_9" type="box"
              size="0.0122474 0.0122474 0.00666578"
              pos="0 0 0.00666578"
              rgba="0.2 0.7 0.2 0.3" contype="1" conaffinity="0" density="1100"/>

        <!-- Tendon-Sites: unten (in) / oben (out) auf äußerster Kante ±x -->
        <site name="site_in_9_0"  pos="0.0101578 0 0.00386341"  size="0.001" rgba="1 1 0 1"/>
        <site name="site_out_9_0" pos="0.00940428 0 0.0117006" size="0.001" rgba="1 1 0 1"/>
        <site name="site_in_9_1"  pos="-0.0101578 0 0.00386341"  size="0.001" rgba="1 1 0 1"/>
        <site name="site_out_9_1" pos="-0.00940428 0 0.0117006" size="0.001" rgba="1 1 0 1"/>

        <!-- Attachment-Punkt für das nächste Segment am Segmentende: -->
        <body name="seg_9_end" pos="0 0 0.0133316">
      <body name="seg_8" pos="0 0 0">
        <joint name="j_8" type="hinge" axis="0 1 0" pos="0 0 0" stiffness="0.05" damping="0.05" limited="true" range="-30.562747418161972 30.562747418161972" solimplimit="0.9 0.95 0.001" solreflimit="0.01 0.5"/>

        <!-- sichtbare, kollisionslose box-->
        <geom name="g_8" type="box"
              size="0.011087 0.011087 0.00603421"
              pos="0 0 0.00603421"
              rgba="0.6 0.75 0.95 0.3" contype="1" conaffinity="0" density="1100"/>

        <!-- Tendon-Sites: unten (in) / oben (out) auf äußerster Kante ±x -->
        <site name="site_in_8_0"  pos="0.00892119 0 0.00339307"  size="0.001" rgba="1 1 0 1"/>
        <site name="site_out_8_0" pos="0.00822417 0 0.0106421" size="0.001" rgba="1 1 0 1"/>
        <site name="site_in_8_1"  pos="-0.00892119 0 0.00339307"  size="0.001" rgba="1 1 0 1"/>
        <site name="site_out_8_1" pos="-0.00822417 0 0.0106421" size="0.001" rgba="1 1 0 1"/>

        <!-- Attachment-Punkt für das nächste Segment am Segmentende: -->
        <body name="seg_8_end" pos="0 0 0.0120684">
      <body name="seg_7" pos="0 0 0">
        <joint name="j_7" type="hinge" axis="0 1 0" pos="0 0 0" stiffness="0.05" damping="0.05" limited="true" range="-30.562747418161972 30.562747418161972" solimplimit="0.9 0.95 0.001" solreflimit="0.01 0.5"/>

        <!-- sichtbare, kollisionslose box-->
        <geom name="g_7" type="box"
              size="0.0100365 0.0100365 0.00546248"
              pos="0 0 0.00546248"
              rgba="0.2 0.7 0.2 0.3" contype="1" conaffinity="0" density="1100"/>

        <!-- Tendon-Sites: unten (in) / oben (out) auf äußerster Kante ±x -->
        <site name="site_in_7_0"  pos="0.00780171 0 0.00296728"  size="0.001" rgba="1 1 0 1"/>
        <site name="site_out_7_0" pos="0.00715588 0 0.00968389" size="0.001" rgba="1 1 0 1"/>
        <site name="site_in_7_1"  pos="-0.00780171 0 0.00296728"  size="0.001" rgba="1 1 0 1"/>
        <site name="site_out_7_1" pos="-0.00715588 0 0.00968389" size="0.001" rgba="1 1 0 1"/>

        <!-- Attachment-Punkt für das nächste Segment am Segmentende: -->
        <body name="seg_7_end" pos="0 0 0.010925">
      <body name="seg_6" pos="0 0 0">
        <joint name="j_6" type="hinge" axis="0 1 0" pos="0 0 0" stiffness="0.05" damping="0.05" limited="true" range="-30.562747418161972 30.562747418161972" solimplimit="0.9 0.95 0.001" solreflimit="0.01 0.5"/>

        <!-- sichtbare, kollisionslose box-->
        <geom name="g_6" type="box"
              size="0.0090856 0.0090856 0.00494492"
              pos="0 0 0.00494492"
              rgba="0.6 0.75 0.95 0.3" contype="1" conaffinity="0" density="1100"/>

        <!-- Tendon-Sites: unten (in) / oben (out) auf äußerster Kante ±x -->
        <site name="site_in_6_0"  pos="0.00678829 0 0.00258184"  size="0.001" rgba="1 1 0 1"/>
        <site name="site_out_6_0" pos="0.00618881 0 0.00881649" size="0.001" rgba="1 1 0 1"/>
        <site name="site_in_6_1"  pos="-0.00678829 0 0.00258184"  size="0.001" rgba="1 1 0 1"/>
        <site name="site_out_6_1" pos="-0.00618881 0 0.00881649" size="0.001" rgba="1 1 0 1"/>

        <!-- Attachment-Punkt für das nächste Segment am Segmentende: -->
        <body name="seg_6_end" pos="0 0 0.00988983">
      <body name="seg_5" pos="0 0 0">
        <joint name="j_5" type="hinge" axis="0 1 0" pos="0 0 0" stiffness="0.05" damping="0.05" limited="true" range="-30.562747418161972 30.562747418161972" solimplimit="0.9 0.95 0.001" solreflimit="0.01 0.5"/>

        <!-- sichtbare, kollisionslose box-->
        <geom name="g_5" type="box"
              size="0.00822476 0.00822476 0.00447639"
              pos="0 0 0.00447639"
              rgba="0.2 0.7 0.2 0.3" contype="1" conaffinity="0" density="1100"/>

        <!-- Tendon-Sites: unten (in) / oben (out) auf äußerster Kante ±x -->
        <site name="site_in_5_0"  pos="0.0058709 0 0.00223292"  size="0.001" rgba="1 1 0 1"/>
        <site name="site_out_5_0" pos="0.00531336 0 0.00803128" size="0.001" rgba="1 1 0 1"/>
        <site name="site_in_5_1"  pos="-0.0058709 0 0.00223292"  size="0.001" rgba="1 1 0 1"/>
        <site name="site_out_5_1" pos="-0.00531336 0 0.00803128" size="0.001" rgba="1 1 0 1"/>

        <!-- Attachment-Punkt für das nächste Segment am Segmentende: -->
        <body name="seg_5_end" pos="0 0 0.00895279">
      <body name="seg_4" pos="0 0 0">
        <joint name="j_4" type="hinge" axis="0 1 0" pos="0 0 0" stiffness="0.05" damping="0.05" limited="true" range="-30.562747418161972 30.562747418161972" solimplimit="0.9 0.95 0.001" solreflimit="0.01 0.5"/>

        <!-- sichtbare, kollisionslose box-->
        <geom name="g_4" type="box"
              size="0.00744548 0.00744548 0.00405226"
              pos="0 0 0.00405226"
              rgba="0.6 0.75 0.95 0.3" contype="1" conaffinity="0" density="1100"/>

        <!-- Tendon-Sites: unten (in) / oben (out) auf äußerster Kante ±x -->
        <site name="site_in_4_0"  pos="0.00504042 0 0.00191706"  size="0.001" rgba="1 1 0 1"/>
        <site name="site_out_4_0" pos="0.00452087 0 0.00732046" size="0.001" rgba="1 1 0 1"/>
        <site name="site_in_4_1"  pos="-0.00504042 0 0.00191706"  size="0.001" rgba="1 1 0 1"/>
        <site name="site_out_4_1" pos="-0.00452087 0 0.00732046" size="0.001" rgba="1 1 0 1"/>

        <!-- Attachment-Punkt für das nächste Segment am Segmentende: -->
        <body name="seg_4_end" pos="0 0 0.00810453">
      <body name="seg_3" pos="0 0 0">
        <joint name="j_3" type="hinge" axis="0 1 0" pos="0 0 0" stiffness="0.05" damping="0.05" limited="true" range="-30.562747418161972 30.562747418161972" solimplimit="0.9 0.95 0.001" solreflimit="0.01 0.5"/>

        <!-- sichtbare, kollisionslose box-->
        <geom name="g_3" type="box"
              size="0.00674003 0.00674003 0.00366832"
              pos="0 0 0.00366832"
              rgba="0.2 0.7 0.2 0.3" contype="1" conaffinity="0" density="1100"/>

        <!-- Tendon-Sites: unten (in) / oben (out) auf äußerster Kante ±x -->
        <site name="site_in_3_0"  pos="0.00428864 0 0.00163113"  size="0.001" rgba="1 1 0 1"/>
        <site name="site_out_3_0" pos="0.00380346 0 0.006677" size="0.001" rgba="1 1 0 1"/>
        <site name="site_in_3_1"  pos="-0.00428864 0 0.00163113"  size="0.001" rgba="1 1 0 1"/>
        <site name="site_out_3_1" pos="-0.00380346 0 0.006677" size="0.001" rgba="1 1 0 1"/>

        <!-- Attachment-Punkt für das nächste Segment am Segmentende: -->
        <body name="seg_3_end" pos="0 0 0.00733664">
      <body name="seg_2" pos="0 0 0">
        <joint name="j_2" type="hinge" axis="0 1 0" pos="0 0 0" stiffness="0.05" damping="0.05" limited="true" range="-30.562747418161972 30.562747418161972" solimplimit="0.9 0.95 0.001" solreflimit="0.01 0.5"/>

        <!-- sichtbare, kollisionslose box-->
        <geom name="g_2" type="box"
              size="0.00610142 0.00610142 0.00332075"
              pos="0 0 0.00332075"
              rgba="0.6 0.75 0.95 0.3" contype="1" conaffinity="0" density="1100"/>

        <!-- Tendon-Sites: unten (in) / oben (out) auf äußerster Kante ±x -->
        <site name="site_in_2_0"  pos="0.00360808 0 0.00137229"  size="0.001" rgba="1 1 0 1"/>
        <site name="site_out_2_0" pos="0.00315402 0 0.0060945" size="0.001" rgba="1 1 0 1"/>
        <site name="site_in_2_1"  pos="-0.00360808 0 0.00137229"  size="0.001" rgba="1 1 0 1"/>
        <site name="site_out_2_1" pos="-0.00315402 0 0.0060945" size="0.001" rgba="1 1 0 1"/>

        <!-- Attachment-Punkt für das nächste Segment am Segmentende: -->
        <body name="seg_2_end" pos="0 0 0.0066415">
      <body name="seg_1" pos="0 0 0">
        <joint name="j_1" type="hinge" axis="0 1 0" pos="0 0 0" stiffness="0.05" damping="0.05" limited="true" range="-30.562747418161972 30.562747418161972" solimplimit="0.9 0.95 0.001" solreflimit="0.01 0.5"/>

        <!-- sichtbare, kollisionslose box-->
        <geom name="g_1" type="box"
              size="0.00552333 0.00552333 0.00300612"
              pos="0 0 0.00300612"
              rgba="0.2 0.7 0.2 0.3" contype="1" conaffinity="0" density="1100"/>

        <!-- Tendon-Sites: unten (in) / oben (out) auf äußerster Kante ±x -->
        <site name="site_in_1_0"  pos="0.002992 0 0.00113797"  size="0.001" rgba="1 1 0 1"/>
        <site name="site_out_1_0" pos="0.00256612 0 0.00556719" size="0.001" rgba="1 1 0 1"/>
        <site name="site_in_1_1"  pos="-0.002992 0 0.00113797"  size="0.001" rgba="1 1 0 1"/>
        <site name="site_out_1_1" pos="-0.00256612 0 0.00556719" size="0.001" rgba="1 1 0 1"/>

        <!-- Attachment-Punkt für das nächste Segment am Segmentende: -->
        <body name="seg_1_end" pos="0 0 0.00601223">
      <body name="seg_0" pos="0 0 0">
        <joint name="j_0" type="hinge" axis="0 1 0" pos="0 0 0" stiffness="0.05" damping="0.05" limited="true" range="-30.562747418161972 30.562747418161972" solimplimit="0.9 0.95 0.001" solreflimit="0.01 0.5"/>

        <!-- sichtbare, kollisionslose box-->
        <geom name="g_0" type="box"
              size="0.005 0.005 0.00272129"
              pos="0 0 0.00272129"
              rgba="0.6 0.75 0.95 0.3" contype="1" conaffinity="0" density="1100"/>

        <!-- Tendon-Sites: unten (in) / oben (out) auf äußerster Kante ±x -->
        <site name="site_in_0_0"  pos="0.0024343 0 0.000925856"  size="0.001" rgba="1 1 0 1"/>
        <site name="site_out_0_0" pos="0.00203392 0 0.00508984" size="0.001" rgba="1 1 0 1"/>
        <site name="site_in_0_1"  pos="-0.0024343 0 0.000925856"  size="0.001" rgba="1 1 0 1"/>
        <site name="site_out_0_1" pos="-0.00203392 0 0.00508984" size="0.001" rgba="1 1 0 1"/>

        <!-- Attachment-Punkt für das nächste Segment am Segmentende: -->
        <body name="seg_0_end" pos="0 0 0.00544258">
        </body>
      </body>
        </body>
      </body>
        </body>
      </body>
        </body>
      </body>
        </body>
      </body>
        </body>
      </body>
        </body>
      </body>
        </body>
      </body>
        </body>
      </body>
        </body>
      </body>
        </body>
      </body>
        </body>
      </body>
        </body>
      </body>
        </body>
      </body>
        </body>
      </body>
        </body>
      </body>
        </body>
      </body>
        </body>
      </body>
    </body>
  </worldbody>
  <tendon>
    <spatial name="tendon_0" width="0.001" rgba="1 0 0 1" frictionloss="0.1" stiffness="50">
      <site site="site_in_17_0"/>
      <site site="site_out_17_0"/>
      <site site="site_in_16_0"/>
      <site site="site_out_16_0"/>
      <site site="site_in_15_0"/>
      <site site="site_out_15_0"/>
      <site site="site_in_14_0"/>
      <site site="site_out_14_0"/>
      <site site="site_in_13_0"/>
      <site site="site_out_13_0"/>
      <site site="site_in_12_0"/>
      <site site="site_out_12_0"/>
      <site site="site_in_11_0"/>
      <site site="site_out_11_0"/>
      <site site="site_in_10_0"/>
      <site site="site_out_10_0"/>
      <site site="site_in_9_0"/>
      <site site="site_out_9_0"/>
      <site site="site_in_8_0"/>
      <site site="site_out_8_0"/>
      <site site="site_in_7_0"/>
      <site site="site_out_7_0"/>
      <site site="site_in_6_0"/>
      <site site="site_out_6_0"/>
      <site site="site_in_5_0"/>
      <site site="site_out_5_0"/>
      <site site="site_in_4_0"/>
      <site site="site_out_4_0"/>
      <site site="site_in_3_0"/>
      <site site="site_out_3_0"/>
      <site site="site_in_2_0"/>
      <site site="site_out_2_0"/>
      <site site="site_in_1_0"/>
      <site site="site_out_1_0"/>
      <site site="site_in_0_0"/>
      <site site="site_out_0_0"/>
    </spatial>
    <spatial name="tendon_1" width="0.001" rgba="1 0 0 1" frictionloss="0.1" stiffness="50">
      <site site="site_in_17_1"/>
      <site site="site_out_17_1"/>
      <site site="site_in_16_1"/>
      <site site="site_out_16_1"/>
      <site site="site_in_15_1"/>
      <site site="site_out_15_1"/>
      <site site="site_in_14_1"/>
      <site site="site_out_14_1"/>
      <site site="site_in_13_1"/>
      <site site="site_out_13_1"/>
      <site site="site_in_12_1"/>
      <site site="site_out_12_1"/>
      <site site="site_in_11_1"/>
      <site site="site_out_11_1"/>
      <site site="site_in_10_1"/>
      <site site="site_out_10_1"/>
      <site site="site_in_9_1"/>
      <site site="site_out_9_1"/>
      <site site="site_in_8_1"/>
      <site site="site_out_8_1"/>
      <site site="site_in_7_1"/>
      <site site="site_out_7_1"/>
      <site site="site_in_6_1"/>
      <site site="site_out_6_1"/>
      <site site="site_in_5_1"/>
      <site site="site_out_5_1"/>
      <site site="site_in_4_1"/>
      <site site="site_out_4_1"/>
      <site site="site_in_3_1"/>
      <site site="site_out_3_1"/>
      <site site="site_in_2_1"/>
      <site site="site_out_2_1"/>
      <site site="site_in_1_1"/>
      <site site="site_out_1_1"/>
      <site site="site_in_0_1"/>
      <site site="site_out_0_1"/>
    </spatial>
  </tendon>
  <actuator>
    <position name="tendon_act_0" tendon="tendon_0" kp="200.0" forcerange="-200 0" ctrlrange="0.00 0.5"/>
    <position name="tendon_act_1" tendon="tendon_1" kp="200.0" forcerange="-200 0" ctrlrange="0.00 0.5"/>
  </actuator>
  <sensor>
    <tendonpos name="tendon0_pos" tendon="tendon_0"/>
    <tendonvel name="tendon0_vel" tendon="tendon_0"/>
    <tendonpos name="tendon1_pos" tendon="tendon_1"/>
    <tendonvel name="tendon1_vel" tendon="tendon_1"/>
  </sensor>

</mujoco>
